<?xml version="1.0" ?>
<robot name="armsimplified-cigarette-new">

<material name="silver">
  <color rgba="0.700 0.700 0.700 1.000"/>
</material>

<link name="base_link">
  <inertial>
    <origin xyz="-0.0001431804689168035 3.518485190128494e-10 0.007056338192618283" rpy="0 0 0"/>
    <mass value="0.31095920589985737"/>
    <inertia ixx="0.00018228002949486542" iyy="0.00033626822261866105" izz="0.00044931614653621465" ixy="4.883798059398419e-13" iyz="-1.6240530198957157e-12" ixz="6.608885838282056e-07"/>
  </inertial>
  <visual>
    <origin xyz="0 0 0" rpy="0 0 0"/>
    <geometry>
      <mesh filename="meshes/base_link.stl" scale="0.001 0.001 0.001"/>
    </geometry>
    <material name="silver"/>
    <material/>
  </visual>
  <collision>
    <origin xyz="0 0 0" rpy="0 0 0"/>
    <geometry>
      <mesh filename="meshes/base_link.stl" scale="0.001 0.001 0.001"/>
    </geometry>
  </collision>
</link>

<link name="Component81">
  <inertial>
    <origin xyz="-6.550390514533483e-06 1.0396631222294776e-17 0.0018412876342259327" rpy="0 0 0"/>
    <mass value="0.1609490715729834"/>
    <inertia ixx="2.7524271105809747e-05" iyy="4.028576791678326e-05" izz="5.183322863913554e-05" ixy="3.2791936780909094e-10" iyz="1.540792906851755e-20" ixz="-7.739767380917053e-09"/>
  </inertial>
  <visual>
    <origin xyz="-0.0 -0.0 -0.0407" rpy="0 0 0"/>
    <geometry>
      <mesh filename="meshes/Component81.stl" scale="0.001 0.001 0.001"/>
    </geometry>
    <material name="silver"/>
    <material/>
  </visual>
  <collision>
    <origin xyz="-0.0 -0.0 -0.0407" rpy="0 0 0"/>
    <geometry>
      <mesh filename="meshes/Component81.stl" scale="0.001 0.001 0.001"/>
    </geometry>
  </collision>
</link>

<link name="Component141">
  <inertial>
    <origin xyz="-0.018999994546847268 2.325784771746402e-08 0.019110039074927088" rpy="0 0 0"/>
    <mass value="0.10089894701692347"/>
    <inertia ixx="4.4188662614157246e-05" iyy="5.824583789343981e-05" izz="2.0675968286208336e-05" ixy="3.5803159968465916e-12" iyz="3.379032645154819e-11" ixz="8.09334846449024e-12"/>
  </inertial>
  <visual>
    <origin xyz="-0.019 -0.0 -0.0567" rpy="0 0 0"/>
    <geometry>
      <mesh filename="meshes/Component141.stl" scale="0.001 0.001 0.001"/>
    </geometry>
    <material name="silver"/>
    <material/>
  </visual>
  <collision>
    <origin xyz="-0.019 -0.0 -0.0567" rpy="0 0 0"/>
    <geometry>
      <mesh filename="meshes/Component141.stl" scale="0.001 0.001 0.001"/>
    </geometry>
  </collision>
</link>

<link name="Component181">
  <inertial>
    <origin xyz="-0.015000782561860116 -0.0026583993766091996 0.000719507187959198" rpy="0 0 0"/>
    <mass value="0.13863430823250342"/>
    <inertia ixx="7.987360640756224e-05" iyy="7.654571826350457e-05" izz="1.5291134098194185e-05" ixy="2.9621293070201167e-10" iyz="-7.017657534773419e-06" ixz="-1.4255337220785136e-10"/>
  </inertial>
  <visual>
    <origin xyz="-0.015 0.0 -0.1067" rpy="0 0 0"/>
    <geometry>
      <mesh filename="meshes/Component181.stl" scale="0.001 0.001 0.001"/>
    </geometry>
    <material name="silver"/>
    <material/>
  </visual>
  <collision>
    <origin xyz="-0.015 0.0 -0.1067" rpy="0 0 0"/>
    <geometry>
      <mesh filename="meshes/Component181.stl" scale="0.001 0.001 0.001"/>
    </geometry>
  </collision>
</link>

<link name="Component211">
  <inertial>
    <origin xyz="0.00044568422756962445 7.837373093590852e-06 -0.01368343846705608" rpy="0 0 0"/>
    <mass value="0.07103948810562974"/>
    <inertia ixx="2.9014062362727562e-05" iyy="2.832798858291071e-05" izz="3.0627148128749514e-06" ixy="-7.948867385366237e-10" iyz="-1.3940718396036794e-08" ixz="-6.803452956453313e-07"/>
  </inertial>
  <visual>
    <origin xyz="0.0 0.0 -0.150517" rpy="0 0 0"/>
    <geometry>
      <mesh filename="meshes/Component211.stl" scale="0.001 0.001 0.001"/>
    </geometry>
    <material name="silver"/>
    <material/>
  </visual>
  <collision>
    <origin xyz="0.0 0.0 -0.150517" rpy="0 0 0"/>
    <geometry>
      <mesh filename="meshes/Component211.stl" scale="0.001 0.001 0.001"/>
    </geometry>
  </collision>
</link>

<link name="wristflex_v11">
  <inertial>
    <origin xyz="-0.004325266658693454 1.3884727557366653e-07 0.007873194374792308" rpy="0 0 0"/>
    <mass value="0.028448493325534164"/>
    <inertia ixx="3.5093105822864073e-06" iyy="2.8363016484203108e-06" izz="1.1472570139368951e-06" ixy="-4.4513519527264884e-11" iyz="-1.9548034286078233e-10" ixz="-1.925924871618621e-07"/>
  </inertial>
  <visual>
    <origin xyz="-0.001488 -3.3e-05 -0.162617" rpy="0 0 0"/>
    <geometry>
      <mesh filename="meshes/wristflex_v11.stl" scale="0.001 0.001 0.001"/>
    </geometry>
    <material name="silver"/>
    <material/>
  </visual>
  <collision>
    <origin xyz="-0.001488 -3.3e-05 -0.162617" rpy="0 0 0"/>
    <geometry>
      <mesh filename="meshes/wristflex_v11.stl" scale="0.001 0.001 0.001"/>
    </geometry>
  </collision>
</link>

<link name="Component261">
  <inertial>
    <origin xyz="-0.0035305069405794647 -1.0249744473569043e-12 0.03769881284204432" rpy="0 0 0"/>
    <mass value="0.11692794330305231"/>
    <inertia ixx="0.0001396504297537975" iyy="0.0001449991873714333" izz="7.677618926657312e-06" ixy="-1.1989797379313584e-14" iyz="-4.1392855095848946e-15" ixz="-8.279465308613681e-06"/>
  </inertial>
  <visual>
    <origin xyz="-0.0 -0.0 -0.1847" rpy="0 0 0"/>
    <geometry>
      <mesh filename="meshes/Component261.stl" scale="0.001 0.001 0.001"/>
    </geometry>
    <material name="silver"/>
    <material/>
  </visual>
  <collision>
    <origin xyz="-0.0 -0.0 -0.1847" rpy="0 0 0"/>
    <geometry>
      <mesh filename="meshes/Component261.stl" scale="0.001 0.001 0.001"/>
    </geometry>
  </collision>
</link>

<link name="Component271">
  <inertial>
    <origin xyz="-4.1657259589788583e-13 -1.9818656883906908e-17 0.0005000021494925844" rpy="0 0 0"/>
    <mass value="0.0003847810901144548"/>
    <inertia ixx="1.5329515379587763e-09" iyy="1.5329519273838679e-09" izz="3.001773283671478e-09" ixy="-6.808789611441789e-25" iyz="5.599887402887576e-23" ixz="7.133158800641323e-23"/>
  </inertial>
  <visual>
    <origin xyz="0.0 0.0 -0.3144" rpy="0 0 0"/>
    <geometry>
      <mesh filename="meshes/Component271.stl" scale="0.001 0.001 0.001"/>
    </geometry>
    <material name="silver"/>
    <material/>
  </visual>
  <collision>
    <origin xyz="0.0 0.0 -0.3144" rpy="0 0 0"/>
    <geometry>
      <mesh filename="meshes/Component271.stl" scale="0.001 0.001 0.001"/>
    </geometry>
  </collision>
</link>

<joint name="Revolute_1" type="continuous">
  <origin xyz="0.0 0.0 0.0407" rpy="0 0 0"/>
  <parent link="base_link"/>
  <child link="Component81"/>
  <axis xyz="0.0 0.0 1.0"/>
</joint>
<transmission name="Revolute_1_tran">
  <type>transmission_interface/SimpleTransmission</type>
  <joint name="Revolute_1">
    <hardwareInterface>PositionJointInterface</hardwareInterface>
  </joint>
  <actuator name="Revolute_1_actr">
    <hardwareInterface>PositionJointInterface</hardwareInterface>
    <mechanicalReduction>1</mechanicalReduction>
  </actuator>
</transmission>

<joint name="Revolute_2" type="continuous">
  <origin xyz="0.019 0.0 0.016" rpy="0 0 0"/>
  <parent link="Component81"/>
  <child link="Component141"/>
  <axis xyz="1.0 -0.0 -0.0"/>
</joint>
<transmission name="Revolute_2_tran">
  <type>transmission_interface/SimpleTransmission</type>
  <joint name="Revolute_2">
    <hardwareInterface>PositionJointInterface</hardwareInterface>
  </joint>
  <actuator name="Revolute_2_actr">
    <hardwareInterface>PositionJointInterface</hardwareInterface>
    <mechanicalReduction>1</mechanicalReduction>
  </actuator>
</transmission>

<joint name="Revolute_3" type="continuous">
  <origin xyz="-0.004 -0.0 0.05" rpy="0 0 0"/>
  <parent link="Component141"/>
  <child link="Component181"/>
  <axis xyz="-1.0 -0.0 -0.0"/>
</joint>
<transmission name="Revolute_3_tran">
  <type>transmission_interface/SimpleTransmission</type>
  <joint name="Revolute_3">
    <hardwareInterface>PositionJointInterface</hardwareInterface>
  </joint>
  <actuator name="Revolute_3_actr">
    <hardwareInterface>PositionJointInterface</hardwareInterface>
    <mechanicalReduction>1</mechanicalReduction>
  </actuator>
</transmission>

<joint name="Revolute_4" type="continuous">
  <origin xyz="-0.015 0.0 0.043817" rpy="0 0 0"/>
  <parent link="Component181"/>
  <child link="Component211"/>
  <axis xyz="0.0 0.0 1.0"/>
</joint>
<transmission name="Revolute_4_tran">
  <type>transmission_interface/SimpleTransmission</type>
  <joint name="Revolute_4">
    <hardwareInterface>PositionJointInterface</hardwareInterface>
  </joint>
  <actuator name="Revolute_4_actr">
    <hardwareInterface>PositionJointInterface</hardwareInterface>
    <mechanicalReduction>1</mechanicalReduction>
  </actuator>
</transmission>

<joint name="Revolute_5" type="continuous">
  <origin xyz="0.001488 3.3e-05 0.0121" rpy="0 0 0"/>
  <parent link="Component211"/>
  <child link="wristflex_v11"/>
  <axis xyz="1.0 -0.0 -0.0"/>
</joint>
<transmission name="Revolute_5_tran">
  <type>transmission_interface/SimpleTransmission</type>
  <joint name="Revolute_5">
    <hardwareInterface>PositionJointInterface</hardwareInterface>
  </joint>
  <actuator name="Revolute_5_actr">
    <hardwareInterface>PositionJointInterface</hardwareInterface>
    <mechanicalReduction>1</mechanicalReduction>
  </actuator>
</transmission>

<joint name="Revolute_7" type="continuous">
  <origin xyz="-0.001488 -3.3e-05 0.022083" rpy="0 0 0"/>
  <parent link="wristflex_v11"/>
  <child link="Component261"/>
  <axis xyz="0.0 -0.0 1.0"/>
</joint>
<transmission name="Revolute_7_tran">
  <type>transmission_interface/SimpleTransmission</type>
  <joint name="Revolute_7">
    <hardwareInterface>PositionJointInterface</hardwareInterface>
  </joint>
  <actuator name="Revolute_7_actr">
    <hardwareInterface>PositionJointInterface</hardwareInterface>
    <mechanicalReduction>1</mechanicalReduction>
  </actuator>
</transmission>

<joint name="Revolute_8" type="continuous">
  <origin xyz="-0.0 -0.0 0.1297" rpy="0 0 0"/>
  <parent link="Component261"/>
  <child link="Component271"/>
  <axis xyz="-0.0 -0.0 1.0"/>
</joint>
<transmission name="Revolute_8_tran">
  <type>transmission_interface/SimpleTransmission</type>
  <joint name="Revolute_8">
    <hardwareInterface>PositionJointInterface</hardwareInterface>
  </joint>
  <actuator name="Revolute_8_actr">
    <hardwareInterface>PositionJointInterface</hardwareInterface>
    <mechanicalReduction>1</mechanicalReduction>
  </actuator>
</transmission>

</robot>
